<?xml version="1.0" ?>
<!-- =================================================================================== -->
<!-- |    This document was autogenerated by xacro from diff_bot.xacro                 | -->
<!-- |    EDITING THIS FILE BY HAND IS NOT RECOMMENDED                                 | -->
<!-- =================================================================================== -->
<robot name="diff_bot">
  <material name="silver">
    <color rgba="0.700 0.700 0.700 1.000"/>
  </material>
  <transmission name="Revolute_1_tran">
    <type>transmission_interface/SimpleTransmission</type>
    <joint name="Revolute_1">
      <hardwareInterface>hardware_interface/VelocityJointInterface</hardwareInterface>
    </joint>
    <actuator name="Revolute_1_actr">
      <hardwareInterface>hardware_interface/VelocityJointInterface</hardwareInterface>
      <mechanicalReduction>1</mechanicalReduction>
    </actuator>
  </transmission>
  <transmission name="Revolute_6_tran">
    <type>transmission_interface/SimpleTransmission</type>
    <joint name="Revolute_6">
      <hardwareInterface>hardware_interface/VelocityJointInterface</hardwareInterface>
    </joint>
    <actuator name="Revolute_6_actr">
      <hardwareInterface>hardware_interface/VelocityJointInterface</hardwareInterface>
      <mechanicalReduction>1</mechanicalReduction>
    </actuator>
  </transmission>
  <gazebo>
    <plugin filename="libgazebo_ros_control.so" name="control"/>
  </gazebo>
  <gazebo reference="base_link">
    <material>Gazebo/Silver</material>
    <mu1>0.2</mu1>
    <mu2>0.2</mu2>
    <self_collide>true</self_collide>
    <gravity>true</gravity>
  </gazebo>
  <gazebo reference="left_wheel_1">
    <material>Gazebo/Silver</material>
    <mu1>10</mu1>
    <mu2>10</mu2>
    <self_collide>true</self_collide>
  </gazebo>
  <gazebo reference="castor_wheel_1">
    <material>Gazebo/Silver</material>
    <mu1>0.0</mu1>
    <mu2>0.0</mu2>
    <self_collide>true</self_collide>
  </gazebo>
  <gazebo reference="lidar_1">
    <material>Gazebo/Silver</material>
    <mu1>10</mu1>
    <mu2>10</mu2>
    <self_collide>true</self_collide>
  </gazebo>
  <gazebo reference="imu_1">
    <material>Gazebo/Silver</material>
    <mu1>10</mu1>
    <mu2>10</mu2>
    <self_collide>true</self_collide>
  </gazebo>
  <gazebo reference="right_wheel_1">
    <material>Gazebo/Silver</material>
    <mu1>10</mu1>
    <mu2>10</mu2>
    <self_collide>true</self_collide>
  </gazebo>
  <gazebo reference="camera_1">
    <material>Gazebo/Silver</material>
    <mu1>10</mu1>
    <mu2>10</mu2>
    <self_collide>true</self_collide>
  </gazebo>
  <!--  **********************************************************Gazebo Plugin SETUP********************************************************** -->
  <!--  SENSOR SETUP -->
  <gazebo reference="imu_1">
    <gravity>true</gravity>
    <sensor name="imu_sensor" type="imu">
      <always_on>true</always_on>
      <update_rate>100</update_rate>
      <visualize>true</visualize>
      <topic>__default_topic__</topic>
      <plugin filename="libgazebo_ros_imu_sensor.so" name="imu_plugin">
        <ros>
          <remapping>~/out:=imu_data</remapping>
        </ros>
        <topicName>imu</topicName>
        <bodyName>imu_1</bodyName>
        <updateRateHZ>10.0</updateRateHZ>
        <gaussianNoise>0.0</gaussianNoise>
        <xyzOffset>0 0 0</xyzOffset>
        <rpyOffset>0 0 0</rpyOffset>
        <frameName>imu_1</frameName>
        <initialOrientationAsReference>false</initialOrientationAsReference>
      </plugin>
      <pose>0 0 0 0 0 0</pose>
    </sensor>
  </gazebo>
  <!-- LIDAR SETUP -->
  <gazebo reference="lidar_1">
    <sensor name="laser" type="ray">
      <pose> 0 0 0 0 0 0 </pose>
      <visualize>false</visualize>
      <update_rate>30</update_rate>
      <ray>
        <scan>
          <horizontal>
            <samples>720</samples>
            <min_angle>-3.14</min_angle>
            <max_angle>3.14</max_angle>
          </horizontal>
        </scan>
        <range>
          <min>0.2</min>
          <max>8</max>
        </range>
      </ray>
      <plugin filename="libgazebo_ros_ray_sensor.so" name="laser_controller">
        <ros>
          <remapping>~/out:=scan</remapping>
        </ros>
        <output_type>sensor_msgs/LaserScan</output_type>
        <frame_name>lidar_1</frame_name>
      </plugin>
    </sensor>
  </gazebo>
  <!-- CAMERA SETUP -->
  <gazebo reference="camera_1">
    <sensor name="camera1" type="camera">
      <update_rate>30.0</update_rate>
      <camera name="head">
        <horizontal_fov>1.3962634</horizontal_fov>
        <!-- <horizontal_fov>2.0</horizontal_fov> -->
        <image>
          <width>800</width>
          <height>800</height>
          <format>R8G8B8</format>
        </image>
        <clip>
          <near>0.05</near>
          <far>300</far>
        </clip>
        <noise>
          <type>gaussian</type>
          <mean>0.0</mean>
          <stddev>0.007</stddev>
        </noise>
      </camera>
      <plugin filename="libgazebo_ros_camera.so" name="camera_controller">
        <alwaysOn>true</alwaysOn>
        <updateRate>30.0</updateRate>
        <cameraName>Camera_1</cameraName>
        <imageTopicName>image_raw</imageTopicName>
        <cameraInfoTopicName>camera_info</cameraInfoTopicName>
        <frameName>Camera_1</frameName>
        <hackBaseline>0.07</hackBaseline>
        <distortionK1>0.0</distortionK1>
        <distortionK2>0.0</distortionK2>
        <distortionK3>0.0</distortionK3>
        <distortionT1>0.0</distortionT1>
        <distortionT2>0.0</distortionT2>
      </plugin>
    </sensor>
  </gazebo>
  <gazebo>
    <plugin filename="libgazebo_ros2_control.so" name="gazebo_ros2_control">
      <parameters>/home/paradox/freelancing_ws/install/diff_bot_description/share/diff_bot_description/config/diff_controller.yaml</parameters>
    </plugin>
  </gazebo>
  <!-- <xacro:include filename="$(find diff_bot_description)/urdf/diff_bot_ros2_control.xacro" /> -->
  <link name="base_footprint"/>
  <link name="base_link">
    <inertial>
      <origin rpy="0 0 0" xyz="-0.0013589333031891648 -1.3322676295501878e-17 0.029506427403050164"/>
      <mass value="7.939615023306801"/>
      <inertia ixx="0.008213" ixy="0.0" ixz="-0.000307" iyy="0.028082" iyz="-0.0" izz="0.032795"/>
    </inertial>
    <visual>
      <origin rpy="0 0 0" xyz="0 0 0"/>
      <geometry>
        <mesh filename="file:///home/paradox/freelancing_ws/install/diff_bot_description/share/diff_bot_description/meshes/base_link.stl" scale="0.001 0.001 0.001"/>
      </geometry>
      <material name="silver"/>
    </visual>
    <collision>
      <origin rpy="0 0 0" xyz="0 0 0"/>
      <geometry>
        <mesh filename="file:///home/paradox/freelancing_ws/install/diff_bot_description/share/diff_bot_description/meshes/base_link.stl" scale="0.001 0.001 0.001"/>
      </geometry>
    </collision>
  </link>
  <link name="left_wheel_1">
    <inertial>
      <origin rpy="0 0 0" xyz="0.0 -0.012500000000000011 0.0"/>
      <mass value="0.9658815551055747"/>
      <inertia ixx="0.000428" ixy="-0.0" ixz="0.0" iyy="0.000758" iyz="-0.0" izz="0.000428"/>
    </inertial>
    <visual>
      <origin rpy="0 0 0" xyz="-0.05 0.05 -0.005"/>
      <geometry>
        <mesh filename="file:///home/paradox/freelancing_ws/install/diff_bot_description/share/diff_bot_description/meshes/left_wheel_1.stl" scale="0.001 0.001 0.001"/>
      </geometry>
      <material name="silver"/>
    </visual>
    <collision>
      <origin rpy="0 0 0" xyz="-0.05 0.05 -0.005"/>
      <geometry>
        <mesh filename="file:///home/paradox/freelancing_ws/install/diff_bot_description/share/diff_bot_description/meshes/left_wheel_1.stl" scale="0.001 0.001 0.001"/>
      </geometry>
    </collision>
  </link>
  <link name="castor_wheel_1">
    <inertial>
      <origin rpy="0 0 0" xyz="6.938893903907228e-18 -8.881784197001253e-18 -0.01124999999999999"/>
      <mass value="0.4439070419522377"/>
      <inertia ixx="0.000104" ixy="-0.0" ixz="0.0" iyy="0.000104" iyz="0.0" izz="0.00016"/>
    </inertial>
    <visual>
      <origin rpy="0 0 0" xyz="0.06 -0.0 0.005"/>
      <geometry>
        <mesh filename="file:///home/paradox/freelancing_ws/install/diff_bot_description/share/diff_bot_description/meshes/castor_wheel_1.stl" scale="0.001 0.001 0.001"/>
      </geometry>
      <material name="silver"/>
    </visual>
    <collision>
      <origin rpy="0 0 0" xyz="0.06 -0.0 0.005"/>
      <geometry>
        <mesh filename="file:///home/paradox/freelancing_ws/install/diff_bot_description/share/diff_bot_description/meshes/castor_wheel_1.stl" scale="0.001 0.001 0.001"/>
      </geometry>
    </collision>
  </link>
  <link name="lidar_1">
    <inertial>
      <origin rpy="0 0 0" xyz="8.881784197001253e-18 2.220446049250313e-18 0.00976987914267307"/>
      <mass value="0.19229515327817076"/>
      <inertia ixx="2.5e-05" ixy="-0.0" ixz="0.0" iyy="2.5e-05" iyz="0.0" izz="3.8e-05"/>
    </inertial>
    <visual>
      <origin rpy="0 0 0" xyz="-0.0 -0.0 -0.055"/>
      <geometry>
        <mesh filename="file:///home/paradox/freelancing_ws/install/diff_bot_description/share/diff_bot_description/meshes/lidar_1.stl" scale="0.001 0.001 0.001"/>
      </geometry>
      <material name="silver"/>
    </visual>
    <collision>
      <origin rpy="0 0 0" xyz="-0.0 -0.0 -0.055"/>
      <geometry>
        <mesh filename="file:///home/paradox/freelancing_ws/install/diff_bot_description/share/diff_bot_description/meshes/lidar_1.stl" scale="0.001 0.001 0.001"/>
      </geometry>
    </collision>
  </link>
  <link name="imu_1">
    <inertial>
      <origin rpy="0 0 0" xyz="0.0875 -0.02 -0.0075"/>
      <mass value="0.003925"/>
      <inertia ixx="0.0" ixy="0.0" ixz="0.0" iyy="0.0" iyz="0.0" izz="0.0"/>
    </inertial>
    <visual>
      <origin rpy="0 0 0" xyz="0.0875 -0.02 -0.01"/>
      <geometry>
        <mesh filename="file:///home/paradox/freelancing_ws/install/diff_bot_description/share/diff_bot_description/meshes/imu_1.stl" scale="0.001 0.001 0.001"/>
      </geometry>
      <material name="silver"/>
    </visual>
    <collision>
      <origin rpy="0 0 0" xyz="0.0875 -0.02 -0.01"/>
      <geometry>
        <mesh filename="file:///home/paradox/freelancing_ws/install/diff_bot_description/share/diff_bot_description/meshes/imu_1.stl" scale="0.001 0.001 0.001"/>
      </geometry>
    </collision>
  </link>
  <link name="right_wheel_1">
    <inertial>
      <origin rpy="0 0 0" xyz="0.0 0.012499999999999997 4.336808689942018e-18"/>
      <mass value="0.9658815551055745"/>
      <inertia ixx="0.000428" ixy="-0.0" ixz="-0.0" iyy="0.000758" iyz="-0.0" izz="0.000428"/>
    </inertial>
    <visual>
      <origin rpy="0 0 0" xyz="-0.05 -0.05 -0.005"/>
      <geometry>
        <mesh filename="file:///home/paradox/freelancing_ws/install/diff_bot_description/share/diff_bot_description/meshes/right_wheel_1.stl" scale="0.001 0.001 0.001"/>
      </geometry>
      <material name="silver"/>
    </visual>
    <collision>
      <origin rpy="0 0 0" xyz="-0.05 -0.05 -0.005"/>
      <geometry>
        <mesh filename="file:///home/paradox/freelancing_ws/install/diff_bot_description/share/diff_bot_description/meshes/right_wheel_1.stl" scale="0.001 0.001 0.001"/>
      </geometry>
    </collision>
  </link>
  <link name="camera_1">
    <inertial>
      <origin rpy="0 0 0" xyz="-0.0049999999999999906 0.0 -6.938893903907228e-18"/>
      <mass value="0.029715375582669967"/>
      <inertia ixx="4e-06" ixy="0.0" ixz="0.0" iyy="0.0" iyz="0.0" izz="4e-06"/>
    </inertial>
    <visual>
      <origin rpy="0 0 0" xyz="0.1 -0.0 -0.055"/>
      <geometry>
        <mesh filename="file:///home/paradox/freelancing_ws/install/diff_bot_description/share/diff_bot_description/meshes/camera_1.stl" scale="0.001 0.001 0.001"/>
      </geometry>
      <material name="silver"/>
    </visual>
    <collision>
      <origin rpy="0 0 0" xyz="0.1 -0.0 -0.055"/>
      <geometry>
        <mesh filename="file:///home/paradox/freelancing_ws/install/diff_bot_description/share/diff_bot_description/meshes/camera_1.stl" scale="0.001 0.001 0.001"/>
      </geometry>
    </collision>
  </link>
  <link name="camera_link_optical"/>
  <joint name="camera_optical_joint" type="fixed">
    <parent link="camera_1"/>
    <child link="camera_link_optical"/>
    <origin rpy="-1.5707963267948966 0 -1.5707963267948966" xyz="0 0 0"/>
  </joint>
  <joint name="footprint_joint" type="fixed">
    <origin rpy="0 0 0" xyz="0 0 0"/>
    <parent link="base_footprint"/>
    <child link="base_link"/>
  </joint>
  <joint name="Revolute_1" type="continuous">
    <origin rpy="0 0 0" xyz="0.05 -0.05 0.005"/>
    <parent link="base_link"/>
    <child link="left_wheel_1"/>
    <axis xyz="0.0 1.0 0.0"/>
  </joint>
  <joint name="Rigid_3" type="fixed">
    <origin rpy="0 0 0" xyz="-0.06 0.0 -0.005"/>
    <parent link="base_link"/>
    <child link="castor_wheel_1"/>
  </joint>
  <joint name="Rigid_4" type="fixed">
    <origin rpy="0 0 0" xyz="0.0 0.0 0.055"/>
    <parent link="base_link"/>
    <child link="lidar_1"/>
  </joint>
  <joint name="Rigid_5" type="fixed">
    <origin rpy="0 0 0" xyz="-0.0875 0.02 0.01"/>
    <parent link="base_link"/>
    <child link="imu_1"/>
  </joint>
  <joint name="Revolute_6" type="continuous">
    <origin rpy="0 0 0" xyz="0.05 0.05 0.005"/>
    <parent link="base_link"/>
    <child link="right_wheel_1"/>
    <axis xyz="0.0 1.0 0.0"/>
  </joint>
  <joint name="Rigid_7" type="fixed">
    <origin rpy="0 0 0" xyz="-0.1 0.0 0.055"/>
    <parent link="base_link"/>
    <child link="camera_1"/>
  </joint>
  <ros2_control name="GazeboSystem" type="system">
    <hardware>
      <plugin>gazebo_ros2_control/GazeboSystem</plugin>
    </hardware>
    <joint name="Revolute_1">
      <command_interface name="velocity">
        <param name="min">-1</param>
        <param name="max">1</param>
      </command_interface>
      <state_interface name="position"/>
      <state_interface name="velocity"/>
    </joint>
    <joint name="Revolute_6">
      <command_interface name="velocity">
        <param name="min">-1</param>
        <param name="max">1</param>
      </command_interface>
      <state_interface name="position"/>
      <state_interface name="velocity"/>
    </joint>
  </ros2_control>
</robot>
